{"level":"ERROR","location":"[On_message:1434] data_ws","message":"'last_traded_time'","timestamp":"2024-02-25 16:10:08,931+0530","service":"FyersDataSocket","exception":"Traceback (most recent call last):\n  File \"C:\\Users\\Admin\\AppData\\Local\\Programs\\Python\\Python311\\Lib\\site-packages\\fyers_apiv3\\FyersWebsocket\\data_ws.py\", line 1425, in On_message\n    self.OnMessage(message)\n  File \"D:\\personal\\AlgoMaster_Trail\\FyersWebSocket.py\", line 40, in onmessage\n    time_stamp = datetime.datetime.fromtimestamp(message['last_traded_time'])\n                                                 ~~~~~~~^^^^^^^^^^^^^^^^^^^^\nKeyError: 'last_traded_time'","exception_name":"KeyError"}
{"level":"ERROR","location":"[__response_output:991] data_ws","message":"string indices must be integers, not 'str'","timestamp":"2024-02-25 16:10:08,936+0530","service":"FyersDataSocket","exception":"Traceback (most recent call last):\n  File \"C:\\Users\\Admin\\AppData\\Local\\Programs\\Python\\Python311\\Lib\\site-packages\\fyers_apiv3\\FyersWebsocket\\data_ws.py\", line 1425, in On_message\n    self.OnMessage(message)\n  File \"D:\\personal\\AlgoMaster_Trail\\FyersWebSocket.py\", line 40, in onmessage\n    time_stamp = datetime.datetime.fromtimestamp(message['last_traded_time'])\n                                                 ~~~~~~~^^^^^^^^^^^^^^^^^^^^\nKeyError: 'last_traded_time'\n\nDuring handling of the above exception, another exception occurred:\n\nTraceback (most recent call last):\n  File \"C:\\Users\\Admin\\AppData\\Local\\Programs\\Python\\Python311\\Lib\\site-packages\\fyers_apiv3\\FyersWebsocket\\data_ws.py\", line 988, in __response_output\n    self.On_message(response)\n  File \"C:\\Users\\Admin\\AppData\\Local\\Programs\\Python\\Python311\\Lib\\site-packages\\fyers_apiv3\\FyersWebsocket\\data_ws.py\", line 1435, in On_message\n    self.On_error(f\"KeyError: The key {key_name} is missing in the response.\")\n  File \"C:\\Users\\Admin\\AppData\\Local\\Programs\\Python\\Python311\\Lib\\site-packages\\fyers_apiv3\\FyersWebsocket\\data_ws.py\", line 1492, in On_error\n    self.OnError(message)\n  File \"D:\\personal\\AlgoMaster_Trail\\FyersWebSocket.py\", line 108, in onerror\n    messages.append(\"Error: \" + str(message[\"message\"]))\n                                    ~~~~~~~^^^^^^^^^^^\nTypeError: string indices must be integers, not 'str'","exception_name":"TypeError"}
{"level":"ERROR","location":"[On_message:1434] data_ws","message":"'last_traded_time'","timestamp":"2024-02-25 16:10:08,940+0530","service":"FyersDataSocket","exception":"Traceback (most recent call last):\n  File \"C:\\Users\\Admin\\AppData\\Local\\Programs\\Python\\Python311\\Lib\\site-packages\\fyers_apiv3\\FyersWebsocket\\data_ws.py\", line 1425, in On_message\n    self.OnMessage(message)\n  File \"D:\\personal\\AlgoMaster_Trail\\FyersWebSocket.py\", line 40, in onmessage\n    time_stamp = datetime.datetime.fromtimestamp(message['last_traded_time'])\n                                                 ~~~~~~~^^^^^^^^^^^^^^^^^^^^\nKeyError: 'last_traded_time'","exception_name":"KeyError"}
{"level":"ERROR","location":"[__response_output:991] data_ws","message":"string indices must be integers, not 'str'","timestamp":"2024-02-25 16:10:08,942+0530","service":"FyersDataSocket","exception":"Traceback (most recent call last):\n  File \"C:\\Users\\Admin\\AppData\\Local\\Programs\\Python\\Python311\\Lib\\site-packages\\fyers_apiv3\\FyersWebsocket\\data_ws.py\", line 1425, in On_message\n    self.OnMessage(message)\n  File \"D:\\personal\\AlgoMaster_Trail\\FyersWebSocket.py\", line 40, in onmessage\n    time_stamp = datetime.datetime.fromtimestamp(message['last_traded_time'])\n                                                 ~~~~~~~^^^^^^^^^^^^^^^^^^^^\nKeyError: 'last_traded_time'\n\nDuring handling of the above exception, another exception occurred:\n\nTraceback (most recent call last):\n  File \"C:\\Users\\Admin\\AppData\\Local\\Programs\\Python\\Python311\\Lib\\site-packages\\fyers_apiv3\\FyersWebsocket\\data_ws.py\", line 988, in __response_output\n    self.On_message(response)\n  File \"C:\\Users\\Admin\\AppData\\Local\\Programs\\Python\\Python311\\Lib\\site-packages\\fyers_apiv3\\FyersWebsocket\\data_ws.py\", line 1435, in On_message\n    self.On_error(f\"KeyError: The key {key_name} is missing in the response.\")\n  File \"C:\\Users\\Admin\\AppData\\Local\\Programs\\Python\\Python311\\Lib\\site-packages\\fyers_apiv3\\FyersWebsocket\\data_ws.py\", line 1492, in On_error\n    self.OnError(message)\n  File \"D:\\personal\\AlgoMaster_Trail\\FyersWebSocket.py\", line 108, in onerror\n    messages.append(\"Error: \" + str(message[\"message\"]))\n                                    ~~~~~~~^^^^^^^^^^^\nTypeError: string indices must be integers, not 'str'","exception_name":"TypeError"}
{"level":"ERROR","location":"[On_message:1434] data_ws","message":"'last_traded_time'","timestamp":"2024-02-25 16:15:27,495+0530","service":"FyersDataSocket","exception":"Traceback (most recent call last):\n  File \"C:\\Users\\Admin\\AppData\\Local\\Programs\\Python\\Python311\\Lib\\site-packages\\fyers_apiv3\\FyersWebsocket\\data_ws.py\", line 1425, in On_message\n    self.OnMessage(message)\n  File \"D:\\personal\\AlgoMaster_Trail\\FyersWebSocket.py\", line 40, in onmessage\n    time_stamp = datetime.datetime.fromtimestamp(message['last_traded_time'])\n                                                 ~~~~~~~^^^^^^^^^^^^^^^^^^^^\nKeyError: 'last_traded_time'","exception_name":"KeyError"}
{"level":"ERROR","location":"[__response_output:991] data_ws","message":"string indices must be integers, not 'str'","timestamp":"2024-02-25 16:15:27,509+0530","service":"FyersDataSocket","exception":"Traceback (most recent call last):\n  File \"C:\\Users\\Admin\\AppData\\Local\\Programs\\Python\\Python311\\Lib\\site-packages\\fyers_apiv3\\FyersWebsocket\\data_ws.py\", line 1425, in On_message\n    self.OnMessage(message)\n  File \"D:\\personal\\AlgoMaster_Trail\\FyersWebSocket.py\", line 40, in onmessage\n    time_stamp = datetime.datetime.fromtimestamp(message['last_traded_time'])\n                                                 ~~~~~~~^^^^^^^^^^^^^^^^^^^^\nKeyError: 'last_traded_time'\n\nDuring handling of the above exception, another exception occurred:\n\nTraceback (most recent call last):\n  File \"C:\\Users\\Admin\\AppData\\Local\\Programs\\Python\\Python311\\Lib\\site-packages\\fyers_apiv3\\FyersWebsocket\\data_ws.py\", line 988, in __response_output\n    self.On_message(response)\n  File \"C:\\Users\\Admin\\AppData\\Local\\Programs\\Python\\Python311\\Lib\\site-packages\\fyers_apiv3\\FyersWebsocket\\data_ws.py\", line 1435, in On_message\n    self.On_error(f\"KeyError: The key {key_name} is missing in the response.\")\n  File \"C:\\Users\\Admin\\AppData\\Local\\Programs\\Python\\Python311\\Lib\\site-packages\\fyers_apiv3\\FyersWebsocket\\data_ws.py\", line 1492, in On_error\n    self.OnError(message)\n  File \"D:\\personal\\AlgoMaster_Trail\\FyersWebSocket.py\", line 108, in onerror\n    messages.append(\"Error: \" + str(message[\"message\"]))\n                                    ~~~~~~~^^^^^^^^^^^\nTypeError: string indices must be integers, not 'str'","exception_name":"TypeError"}
{"level":"ERROR","location":"[On_message:1434] data_ws","message":"'last_traded_time'","timestamp":"2024-02-25 16:15:27,511+0530","service":"FyersDataSocket","exception":"Traceback (most recent call last):\n  File \"C:\\Users\\Admin\\AppData\\Local\\Programs\\Python\\Python311\\Lib\\site-packages\\fyers_apiv3\\FyersWebsocket\\data_ws.py\", line 1425, in On_message\n    self.OnMessage(message)\n  File \"D:\\personal\\AlgoMaster_Trail\\FyersWebSocket.py\", line 40, in onmessage\n    time_stamp = datetime.datetime.fromtimestamp(message['last_traded_time'])\n                                                 ~~~~~~~^^^^^^^^^^^^^^^^^^^^\nKeyError: 'last_traded_time'","exception_name":"KeyError"}
{"level":"ERROR","location":"[__response_output:991] data_ws","message":"string indices must be integers, not 'str'","timestamp":"2024-02-25 16:15:27,516+0530","service":"FyersDataSocket","exception":"Traceback (most recent call last):\n  File \"C:\\Users\\Admin\\AppData\\Local\\Programs\\Python\\Python311\\Lib\\site-packages\\fyers_apiv3\\FyersWebsocket\\data_ws.py\", line 1425, in On_message\n    self.OnMessage(message)\n  File \"D:\\personal\\AlgoMaster_Trail\\FyersWebSocket.py\", line 40, in onmessage\n    time_stamp = datetime.datetime.fromtimestamp(message['last_traded_time'])\n                                                 ~~~~~~~^^^^^^^^^^^^^^^^^^^^\nKeyError: 'last_traded_time'\n\nDuring handling of the above exception, another exception occurred:\n\nTraceback (most recent call last):\n  File \"C:\\Users\\Admin\\AppData\\Local\\Programs\\Python\\Python311\\Lib\\site-packages\\fyers_apiv3\\FyersWebsocket\\data_ws.py\", line 988, in __response_output\n    self.On_message(response)\n  File \"C:\\Users\\Admin\\AppData\\Local\\Programs\\Python\\Python311\\Lib\\site-packages\\fyers_apiv3\\FyersWebsocket\\data_ws.py\", line 1435, in On_message\n    self.On_error(f\"KeyError: The key {key_name} is missing in the response.\")\n  File \"C:\\Users\\Admin\\AppData\\Local\\Programs\\Python\\Python311\\Lib\\site-packages\\fyers_apiv3\\FyersWebsocket\\data_ws.py\", line 1492, in On_error\n    self.OnError(message)\n  File \"D:\\personal\\AlgoMaster_Trail\\FyersWebSocket.py\", line 108, in onerror\n    messages.append(\"Error: \" + str(message[\"message\"]))\n                                    ~~~~~~~^^^^^^^^^^^\nTypeError: string indices must be integers, not 'str'","exception_name":"TypeError"}
{"level":"ERROR","location":"[On_message:1434] data_ws","message":"'last_traded_time'","timestamp":"2024-02-25 16:17:37,645+0530","service":"FyersDataSocket","exception":"Traceback (most recent call last):\n  File \"C:\\Users\\Admin\\AppData\\Local\\Programs\\Python\\Python311\\Lib\\site-packages\\fyers_apiv3\\FyersWebsocket\\data_ws.py\", line 1425, in On_message\n    self.OnMessage(message)\n  File \"D:\\personal\\AlgoMaster_Trail\\FyersWebSocket.py\", line 40, in onmessage\n    time_stamp = datetime.datetime.fromtimestamp(message['last_traded_time'])\n                                                 ~~~~~~~^^^^^^^^^^^^^^^^^^^^\nKeyError: 'last_traded_time'","exception_name":"KeyError"}
{"level":"ERROR","location":"[__response_output:991] data_ws","message":"string indices must be integers, not 'str'","timestamp":"2024-02-25 16:17:37,653+0530","service":"FyersDataSocket","exception":"Traceback (most recent call last):\n  File \"C:\\Users\\Admin\\AppData\\Local\\Programs\\Python\\Python311\\Lib\\site-packages\\fyers_apiv3\\FyersWebsocket\\data_ws.py\", line 1425, in On_message\n    self.OnMessage(message)\n  File \"D:\\personal\\AlgoMaster_Trail\\FyersWebSocket.py\", line 40, in onmessage\n    time_stamp = datetime.datetime.fromtimestamp(message['last_traded_time'])\n                                                 ~~~~~~~^^^^^^^^^^^^^^^^^^^^\nKeyError: 'last_traded_time'\n\nDuring handling of the above exception, another exception occurred:\n\nTraceback (most recent call last):\n  File \"C:\\Users\\Admin\\AppData\\Local\\Programs\\Python\\Python311\\Lib\\site-packages\\fyers_apiv3\\FyersWebsocket\\data_ws.py\", line 988, in __response_output\n    self.On_message(response)\n  File \"C:\\Users\\Admin\\AppData\\Local\\Programs\\Python\\Python311\\Lib\\site-packages\\fyers_apiv3\\FyersWebsocket\\data_ws.py\", line 1435, in On_message\n    self.On_error(f\"KeyError: The key {key_name} is missing in the response.\")\n  File \"C:\\Users\\Admin\\AppData\\Local\\Programs\\Python\\Python311\\Lib\\site-packages\\fyers_apiv3\\FyersWebsocket\\data_ws.py\", line 1492, in On_error\n    self.OnError(message)\n  File \"D:\\personal\\AlgoMaster_Trail\\FyersWebSocket.py\", line 108, in onerror\n    messages.append(\"Error: \" + str(message[\"message\"]))\n                                    ~~~~~~~^^^^^^^^^^^\nTypeError: string indices must be integers, not 'str'","exception_name":"TypeError"}
{"level":"ERROR","location":"[On_message:1434] data_ws","message":"'last_traded_time'","timestamp":"2024-02-25 16:17:37,661+0530","service":"FyersDataSocket","exception":"Traceback (most recent call last):\n  File \"C:\\Users\\Admin\\AppData\\Local\\Programs\\Python\\Python311\\Lib\\site-packages\\fyers_apiv3\\FyersWebsocket\\data_ws.py\", line 1425, in On_message\n    self.OnMessage(message)\n  File \"D:\\personal\\AlgoMaster_Trail\\FyersWebSocket.py\", line 40, in onmessage\n    time_stamp = datetime.datetime.fromtimestamp(message['last_traded_time'])\n                                                 ~~~~~~~^^^^^^^^^^^^^^^^^^^^\nKeyError: 'last_traded_time'","exception_name":"KeyError"}
{"level":"ERROR","location":"[__response_output:991] data_ws","message":"string indices must be integers, not 'str'","timestamp":"2024-02-25 16:17:37,666+0530","service":"FyersDataSocket","exception":"Traceback (most recent call last):\n  File \"C:\\Users\\Admin\\AppData\\Local\\Programs\\Python\\Python311\\Lib\\site-packages\\fyers_apiv3\\FyersWebsocket\\data_ws.py\", line 1425, in On_message\n    self.OnMessage(message)\n  File \"D:\\personal\\AlgoMaster_Trail\\FyersWebSocket.py\", line 40, in onmessage\n    time_stamp = datetime.datetime.fromtimestamp(message['last_traded_time'])\n                                                 ~~~~~~~^^^^^^^^^^^^^^^^^^^^\nKeyError: 'last_traded_time'\n\nDuring handling of the above exception, another exception occurred:\n\nTraceback (most recent call last):\n  File \"C:\\Users\\Admin\\AppData\\Local\\Programs\\Python\\Python311\\Lib\\site-packages\\fyers_apiv3\\FyersWebsocket\\data_ws.py\", line 988, in __response_output\n    self.On_message(response)\n  File \"C:\\Users\\Admin\\AppData\\Local\\Programs\\Python\\Python311\\Lib\\site-packages\\fyers_apiv3\\FyersWebsocket\\data_ws.py\", line 1435, in On_message\n    self.On_error(f\"KeyError: The key {key_name} is missing in the response.\")\n  File \"C:\\Users\\Admin\\AppData\\Local\\Programs\\Python\\Python311\\Lib\\site-packages\\fyers_apiv3\\FyersWebsocket\\data_ws.py\", line 1492, in On_error\n    self.OnError(message)\n  File \"D:\\personal\\AlgoMaster_Trail\\FyersWebSocket.py\", line 108, in onerror\n    messages.append(\"Error: \" + str(message[\"message\"]))\n                                    ~~~~~~~^^^^^^^^^^^\nTypeError: string indices must be integers, not 'str'","exception_name":"TypeError"}
{"level":"ERROR","location":"[On_message:1434] data_ws","message":"'last_traded_time'","timestamp":"2024-02-25 16:21:59,661+0530","service":"FyersDataSocket","exception":"Traceback (most recent call last):\n  File \"C:\\Users\\Admin\\AppData\\Local\\Programs\\Python\\Python311\\Lib\\site-packages\\fyers_apiv3\\FyersWebsocket\\data_ws.py\", line 1425, in On_message\n    self.OnMessage(message)\n  File \"D:\\personal\\AlgoMaster_Trail\\FyersWebSocket.py\", line 40, in onmessage\n    time_stamp = datetime.datetime.fromtimestamp(message['last_traded_time'])\n                                                 ~~~~~~~^^^^^^^^^^^^^^^^^^^^\nKeyError: 'last_traded_time'","exception_name":"KeyError"}
{"level":"ERROR","location":"[__response_output:991] data_ws","message":"string indices must be integers, not 'str'","timestamp":"2024-02-25 16:21:59,664+0530","service":"FyersDataSocket","exception":"Traceback (most recent call last):\n  File \"C:\\Users\\Admin\\AppData\\Local\\Programs\\Python\\Python311\\Lib\\site-packages\\fyers_apiv3\\FyersWebsocket\\data_ws.py\", line 1425, in On_message\n    self.OnMessage(message)\n  File \"D:\\personal\\AlgoMaster_Trail\\FyersWebSocket.py\", line 40, in onmessage\n    time_stamp = datetime.datetime.fromtimestamp(message['last_traded_time'])\n                                                 ~~~~~~~^^^^^^^^^^^^^^^^^^^^\nKeyError: 'last_traded_time'\n\nDuring handling of the above exception, another exception occurred:\n\nTraceback (most recent call last):\n  File \"C:\\Users\\Admin\\AppData\\Local\\Programs\\Python\\Python311\\Lib\\site-packages\\fyers_apiv3\\FyersWebsocket\\data_ws.py\", line 988, in __response_output\n    self.On_message(response)\n  File \"C:\\Users\\Admin\\AppData\\Local\\Programs\\Python\\Python311\\Lib\\site-packages\\fyers_apiv3\\FyersWebsocket\\data_ws.py\", line 1435, in On_message\n    self.On_error(f\"KeyError: The key {key_name} is missing in the response.\")\n  File \"C:\\Users\\Admin\\AppData\\Local\\Programs\\Python\\Python311\\Lib\\site-packages\\fyers_apiv3\\FyersWebsocket\\data_ws.py\", line 1492, in On_error\n    self.OnError(message)\n  File \"D:\\personal\\AlgoMaster_Trail\\FyersWebSocket.py\", line 108, in onerror\n    messages.append(\"Error: \" + str(message[\"message\"]))\n                                    ~~~~~~~^^^^^^^^^^^\nTypeError: string indices must be integers, not 'str'","exception_name":"TypeError"}
{"level":"ERROR","location":"[On_message:1434] data_ws","message":"'last_traded_time'","timestamp":"2024-02-25 16:30:25,931+0530","service":"FyersDataSocket","exception":"Traceback (most recent call last):\n  File \"C:\\Users\\Admin\\AppData\\Local\\Programs\\Python\\Python311\\Lib\\site-packages\\fyers_apiv3\\FyersWebsocket\\data_ws.py\", line 1425, in On_message\n    self.OnMessage(message)\n  File \"D:\\personal\\AlgoMaster_Trail\\FyersWebSocket.py\", line 40, in onmessage\n    time_stamp = datetime.datetime.fromtimestamp(message['last_traded_time'])\n                                                 ~~~~~~~^^^^^^^^^^^^^^^^^^^^\nKeyError: 'last_traded_time'","exception_name":"KeyError"}
{"level":"ERROR","location":"[__response_output:991] data_ws","message":"string indices must be integers, not 'str'","timestamp":"2024-02-25 16:30:25,933+0530","service":"FyersDataSocket","exception":"Traceback (most recent call last):\n  File \"C:\\Users\\Admin\\AppData\\Local\\Programs\\Python\\Python311\\Lib\\site-packages\\fyers_apiv3\\FyersWebsocket\\data_ws.py\", line 1425, in On_message\n    self.OnMessage(message)\n  File \"D:\\personal\\AlgoMaster_Trail\\FyersWebSocket.py\", line 40, in onmessage\n    time_stamp = datetime.datetime.fromtimestamp(message['last_traded_time'])\n                                                 ~~~~~~~^^^^^^^^^^^^^^^^^^^^\nKeyError: 'last_traded_time'\n\nDuring handling of the above exception, another exception occurred:\n\nTraceback (most recent call last):\n  File \"C:\\Users\\Admin\\AppData\\Local\\Programs\\Python\\Python311\\Lib\\site-packages\\fyers_apiv3\\FyersWebsocket\\data_ws.py\", line 988, in __response_output\n    self.On_message(response)\n  File \"C:\\Users\\Admin\\AppData\\Local\\Programs\\Python\\Python311\\Lib\\site-packages\\fyers_apiv3\\FyersWebsocket\\data_ws.py\", line 1435, in On_message\n    self.On_error(f\"KeyError: The key {key_name} is missing in the response.\")\n  File \"C:\\Users\\Admin\\AppData\\Local\\Programs\\Python\\Python311\\Lib\\site-packages\\fyers_apiv3\\FyersWebsocket\\data_ws.py\", line 1492, in On_error\n    self.OnError(message)\n  File \"D:\\personal\\AlgoMaster_Trail\\FyersWebSocket.py\", line 108, in onerror\n    messages.append(\"Error: \" + str(message[\"message\"]))\n                                    ~~~~~~~^^^^^^^^^^^\nTypeError: string indices must be integers, not 'str'","exception_name":"TypeError"}
{"level":"ERROR","location":"[On_message:1434] data_ws","message":"'last_traded_time'","timestamp":"2024-02-25 16:36:59,979+0530","service":"FyersDataSocket","exception":"Traceback (most recent call last):\n  File \"C:\\Users\\Admin\\AppData\\Local\\Programs\\Python\\Python311\\Lib\\site-packages\\fyers_apiv3\\FyersWebsocket\\data_ws.py\", line 1425, in On_message\n    self.OnMessage(message)\n  File \"D:\\personal\\AlgoMaster_Trail\\FyersWebSocket.py\", line 40, in onmessage\n    time_stamp = datetime.datetime.fromtimestamp(message['last_traded_time'])\n                                                 ~~~~~~~^^^^^^^^^^^^^^^^^^^^\nKeyError: 'last_traded_time'","exception_name":"KeyError"}
{"level":"ERROR","location":"[__response_output:991] data_ws","message":"string indices must be integers, not 'str'","timestamp":"2024-02-25 16:36:59,987+0530","service":"FyersDataSocket","exception":"Traceback (most recent call last):\n  File \"C:\\Users\\Admin\\AppData\\Local\\Programs\\Python\\Python311\\Lib\\site-packages\\fyers_apiv3\\FyersWebsocket\\data_ws.py\", line 1425, in On_message\n    self.OnMessage(message)\n  File \"D:\\personal\\AlgoMaster_Trail\\FyersWebSocket.py\", line 40, in onmessage\n    time_stamp = datetime.datetime.fromtimestamp(message['last_traded_time'])\n                                                 ~~~~~~~^^^^^^^^^^^^^^^^^^^^\nKeyError: 'last_traded_time'\n\nDuring handling of the above exception, another exception occurred:\n\nTraceback (most recent call last):\n  File \"C:\\Users\\Admin\\AppData\\Local\\Programs\\Python\\Python311\\Lib\\site-packages\\fyers_apiv3\\FyersWebsocket\\data_ws.py\", line 988, in __response_output\n    self.On_message(response)\n  File \"C:\\Users\\Admin\\AppData\\Local\\Programs\\Python\\Python311\\Lib\\site-packages\\fyers_apiv3\\FyersWebsocket\\data_ws.py\", line 1435, in On_message\n    self.On_error(f\"KeyError: The key {key_name} is missing in the response.\")\n  File \"C:\\Users\\Admin\\AppData\\Local\\Programs\\Python\\Python311\\Lib\\site-packages\\fyers_apiv3\\FyersWebsocket\\data_ws.py\", line 1492, in On_error\n    self.OnError(message)\n  File \"D:\\personal\\AlgoMaster_Trail\\FyersWebSocket.py\", line 108, in onerror\n    messages.append(\"Error: \" + str(message[\"message\"]))\n                                    ~~~~~~~^^^^^^^^^^^\nTypeError: string indices must be integers, not 'str'","exception_name":"TypeError"}
{"level":"ERROR","location":"[On_message:1434] data_ws","message":"'last_traded_time'","timestamp":"2024-02-25 16:52:31,075+0530","service":"FyersDataSocket","exception":"Traceback (most recent call last):\n  File \"C:\\Users\\Admin\\AppData\\Local\\Programs\\Python\\Python311\\Lib\\site-packages\\fyers_apiv3\\FyersWebsocket\\data_ws.py\", line 1425, in On_message\n    self.OnMessage(message)\n  File \"D:\\personal\\AlgoMaster_Trail\\FyersWebSocket.py\", line 40, in onmessage\n    time_stamp = datetime.datetime.fromtimestamp(message['last_traded_time'])\n                                                 ~~~~~~~^^^^^^^^^^^^^^^^^^^^\nKeyError: 'last_traded_time'","exception_name":"KeyError"}
{"level":"ERROR","location":"[__response_output:991] data_ws","message":"string indices must be integers, not 'str'","timestamp":"2024-02-25 16:52:31,085+0530","service":"FyersDataSocket","exception":"Traceback (most recent call last):\n  File \"C:\\Users\\Admin\\AppData\\Local\\Programs\\Python\\Python311\\Lib\\site-packages\\fyers_apiv3\\FyersWebsocket\\data_ws.py\", line 1425, in On_message\n    self.OnMessage(message)\n  File \"D:\\personal\\AlgoMaster_Trail\\FyersWebSocket.py\", line 40, in onmessage\n    time_stamp = datetime.datetime.fromtimestamp(message['last_traded_time'])\n                                                 ~~~~~~~^^^^^^^^^^^^^^^^^^^^\nKeyError: 'last_traded_time'\n\nDuring handling of the above exception, another exception occurred:\n\nTraceback (most recent call last):\n  File \"C:\\Users\\Admin\\AppData\\Local\\Programs\\Python\\Python311\\Lib\\site-packages\\fyers_apiv3\\FyersWebsocket\\data_ws.py\", line 988, in __response_output\n    self.On_message(response)\n  File \"C:\\Users\\Admin\\AppData\\Local\\Programs\\Python\\Python311\\Lib\\site-packages\\fyers_apiv3\\FyersWebsocket\\data_ws.py\", line 1435, in On_message\n    self.On_error(f\"KeyError: The key {key_name} is missing in the response.\")\n  File \"C:\\Users\\Admin\\AppData\\Local\\Programs\\Python\\Python311\\Lib\\site-packages\\fyers_apiv3\\FyersWebsocket\\data_ws.py\", line 1492, in On_error\n    self.OnError(message)\n  File \"D:\\personal\\AlgoMaster_Trail\\FyersWebSocket.py\", line 108, in onerror\n    messages.append(\"Error: \" + str(message[\"message\"]))\n                                    ~~~~~~~^^^^^^^^^^^\nTypeError: string indices must be integers, not 'str'","exception_name":"TypeError"}
{"level":"ERROR","location":"[On_message:1434] data_ws","message":"'last_traded_time'","timestamp":"2024-02-25 16:52:31,091+0530","service":"FyersDataSocket","exception":"Traceback (most recent call last):\n  File \"C:\\Users\\Admin\\AppData\\Local\\Programs\\Python\\Python311\\Lib\\site-packages\\fyers_apiv3\\FyersWebsocket\\data_ws.py\", line 1425, in On_message\n    self.OnMessage(message)\n  File \"D:\\personal\\AlgoMaster_Trail\\FyersWebSocket.py\", line 40, in onmessage\n    time_stamp = datetime.datetime.fromtimestamp(message['last_traded_time'])\n                                                 ~~~~~~~^^^^^^^^^^^^^^^^^^^^\nKeyError: 'last_traded_time'","exception_name":"KeyError"}
{"level":"ERROR","location":"[__response_output:991] data_ws","message":"string indices must be integers, not 'str'","timestamp":"2024-02-25 16:52:31,094+0530","service":"FyersDataSocket","exception":"Traceback (most recent call last):\n  File \"C:\\Users\\Admin\\AppData\\Local\\Programs\\Python\\Python311\\Lib\\site-packages\\fyers_apiv3\\FyersWebsocket\\data_ws.py\", line 1425, in On_message\n    self.OnMessage(message)\n  File \"D:\\personal\\AlgoMaster_Trail\\FyersWebSocket.py\", line 40, in onmessage\n    time_stamp = datetime.datetime.fromtimestamp(message['last_traded_time'])\n                                                 ~~~~~~~^^^^^^^^^^^^^^^^^^^^\nKeyError: 'last_traded_time'\n\nDuring handling of the above exception, another exception occurred:\n\nTraceback (most recent call last):\n  File \"C:\\Users\\Admin\\AppData\\Local\\Programs\\Python\\Python311\\Lib\\site-packages\\fyers_apiv3\\FyersWebsocket\\data_ws.py\", line 988, in __response_output\n    self.On_message(response)\n  File \"C:\\Users\\Admin\\AppData\\Local\\Programs\\Python\\Python311\\Lib\\site-packages\\fyers_apiv3\\FyersWebsocket\\data_ws.py\", line 1435, in On_message\n    self.On_error(f\"KeyError: The key {key_name} is missing in the response.\")\n  File \"C:\\Users\\Admin\\AppData\\Local\\Programs\\Python\\Python311\\Lib\\site-packages\\fyers_apiv3\\FyersWebsocket\\data_ws.py\", line 1492, in On_error\n    self.OnError(message)\n  File \"D:\\personal\\AlgoMaster_Trail\\FyersWebSocket.py\", line 108, in onerror\n    messages.append(\"Error: \" + str(message[\"message\"]))\n                                    ~~~~~~~^^^^^^^^^^^\nTypeError: string indices must be integers, not 'str'","exception_name":"TypeError"}
{"level":"ERROR","location":"[On_message:1434] data_ws","message":"'last_traded_time'","timestamp":"2024-02-25 16:54:33,356+0530","service":"FyersDataSocket","exception":"Traceback (most recent call last):\n  File \"C:\\Users\\Admin\\AppData\\Local\\Programs\\Python\\Python311\\Lib\\site-packages\\fyers_apiv3\\FyersWebsocket\\data_ws.py\", line 1425, in On_message\n    self.OnMessage(message)\n  File \"D:\\personal\\AlgoMaster_Trail\\FyersWebSocket.py\", line 40, in onmessage\n    time_stamp = datetime.datetime.fromtimestamp(message['last_traded_time'])\n                                                 ~~~~~~~^^^^^^^^^^^^^^^^^^^^\nKeyError: 'last_traded_time'","exception_name":"KeyError"}
{"level":"ERROR","location":"[__response_output:991] data_ws","message":"string indices must be integers, not 'str'","timestamp":"2024-02-25 16:54:33,358+0530","service":"FyersDataSocket","exception":"Traceback (most recent call last):\n  File \"C:\\Users\\Admin\\AppData\\Local\\Programs\\Python\\Python311\\Lib\\site-packages\\fyers_apiv3\\FyersWebsocket\\data_ws.py\", line 1425, in On_message\n    self.OnMessage(message)\n  File \"D:\\personal\\AlgoMaster_Trail\\FyersWebSocket.py\", line 40, in onmessage\n    time_stamp = datetime.datetime.fromtimestamp(message['last_traded_time'])\n                                                 ~~~~~~~^^^^^^^^^^^^^^^^^^^^\nKeyError: 'last_traded_time'\n\nDuring handling of the above exception, another exception occurred:\n\nTraceback (most recent call last):\n  File \"C:\\Users\\Admin\\AppData\\Local\\Programs\\Python\\Python311\\Lib\\site-packages\\fyers_apiv3\\FyersWebsocket\\data_ws.py\", line 988, in __response_output\n    self.On_message(response)\n  File \"C:\\Users\\Admin\\AppData\\Local\\Programs\\Python\\Python311\\Lib\\site-packages\\fyers_apiv3\\FyersWebsocket\\data_ws.py\", line 1435, in On_message\n    self.On_error(f\"KeyError: The key {key_name} is missing in the response.\")\n  File \"C:\\Users\\Admin\\AppData\\Local\\Programs\\Python\\Python311\\Lib\\site-packages\\fyers_apiv3\\FyersWebsocket\\data_ws.py\", line 1492, in On_error\n    self.OnError(message)\n  File \"D:\\personal\\AlgoMaster_Trail\\FyersWebSocket.py\", line 108, in onerror\n    messages.append(\"Error: \" + str(message[\"message\"]))\n                                    ~~~~~~~^^^^^^^^^^^\nTypeError: string indices must be integers, not 'str'","exception_name":"TypeError"}
{"level":"ERROR","location":"[On_message:1434] data_ws","message":"'last_traded_time'","timestamp":"2024-02-25 17:10:42,600+0530","service":"FyersDataSocket","exception":"Traceback (most recent call last):\n  File \"C:\\Users\\Admin\\AppData\\Local\\Programs\\Python\\Python311\\Lib\\site-packages\\fyers_apiv3\\FyersWebsocket\\data_ws.py\", line 1425, in On_message\n    self.OnMessage(message)\n  File \"D:\\personal\\AlgoMaster_Trail\\FyersWebSocket.py\", line 40, in onmessage\n    time_stamp = datetime.datetime.fromtimestamp(message['last_traded_time'])\n                                                 ~~~~~~~^^^^^^^^^^^^^^^^^^^^\nKeyError: 'last_traded_time'","exception_name":"KeyError"}
{"level":"ERROR","location":"[__response_output:991] data_ws","message":"string indices must be integers, not 'str'","timestamp":"2024-02-25 17:10:42,611+0530","service":"FyersDataSocket","exception":"Traceback (most recent call last):\n  File \"C:\\Users\\Admin\\AppData\\Local\\Programs\\Python\\Python311\\Lib\\site-packages\\fyers_apiv3\\FyersWebsocket\\data_ws.py\", line 1425, in On_message\n    self.OnMessage(message)\n  File \"D:\\personal\\AlgoMaster_Trail\\FyersWebSocket.py\", line 40, in onmessage\n    time_stamp = datetime.datetime.fromtimestamp(message['last_traded_time'])\n                                                 ~~~~~~~^^^^^^^^^^^^^^^^^^^^\nKeyError: 'last_traded_time'\n\nDuring handling of the above exception, another exception occurred:\n\nTraceback (most recent call last):\n  File \"C:\\Users\\Admin\\AppData\\Local\\Programs\\Python\\Python311\\Lib\\site-packages\\fyers_apiv3\\FyersWebsocket\\data_ws.py\", line 988, in __response_output\n    self.On_message(response)\n  File \"C:\\Users\\Admin\\AppData\\Local\\Programs\\Python\\Python311\\Lib\\site-packages\\fyers_apiv3\\FyersWebsocket\\data_ws.py\", line 1435, in On_message\n    self.On_error(f\"KeyError: The key {key_name} is missing in the response.\")\n  File \"C:\\Users\\Admin\\AppData\\Local\\Programs\\Python\\Python311\\Lib\\site-packages\\fyers_apiv3\\FyersWebsocket\\data_ws.py\", line 1492, in On_error\n    self.OnError(message)\n  File \"D:\\personal\\AlgoMaster_Trail\\FyersWebSocket.py\", line 108, in onerror\n    messages.append(\"Error: \" + str(message[\"message\"] ))\n                                    ~~~~~~~^^^^^^^^^^^\nTypeError: string indices must be integers, not 'str'","exception_name":"TypeError"}
{"level":"DEBUG","location":"[<lambda>:1654] data_ws","message":"Response:Attempting reconnect 1 of 10...","timestamp":"2024-02-25 17:12:44,406+0530","service":"FyersDataSocket"}
{"level":"DEBUG","location":"[<lambda>:1654] data_ws","message":"Response:Attempting reconnect 2 of 10...","timestamp":"2024-02-25 17:12:49,456+0530","service":"FyersDataSocket"}
{"level":"DEBUG","location":"[<lambda>:1654] data_ws","message":"Response:Attempting reconnect 3 of 10...","timestamp":"2024-02-26 10:14:49,684+0530","service":"FyersDataSocket"}
{"level":"DEBUG","location":"[<lambda>:1654] data_ws","message":"Response:Attempting reconnect 1 of 10...","timestamp":"2024-02-26 11:06:16,797+0530","service":"FyersDataSocket"}
{"level":"DEBUG","location":"[<lambda>:1654] data_ws","message":"Response:Attempting reconnect 2 of 10...","timestamp":"2024-02-26 11:22:21,252+0530","service":"FyersDataSocket"}
{"level":"DEBUG","location":"[<lambda>:1654] data_ws","message":"Response:Attempting reconnect 3 of 10...","timestamp":"2024-02-26 11:31:06,096+0530","service":"FyersDataSocket"}
{"level":"DEBUG","location":"[<lambda>:1654] data_ws","message":"Response:Attempting reconnect 4 of 10...","timestamp":"2024-02-26 11:31:32,189+0530","service":"FyersDataSocket"}
{"level":"DEBUG","location":"[<lambda>:1654] data_ws","message":"Response:Attempting reconnect 5 of 10...","timestamp":"2024-02-26 11:31:37,218+0530","service":"FyersDataSocket"}
{"level":"DEBUG","location":"[<lambda>:1654] data_ws","message":"Response:Attempting reconnect 6 of 10...","timestamp":"2024-02-26 11:31:42,231+0530","service":"FyersDataSocket"}
{"level":"DEBUG","location":"[<lambda>:1654] data_ws","message":"Response:Attempting reconnect 7 of 10...","timestamp":"2024-02-26 11:31:52,245+0530","service":"FyersDataSocket"}
{"level":"DEBUG","location":"[<lambda>:1654] data_ws","message":"Response:Attempting reconnect 8 of 10...","timestamp":"2024-02-26 11:32:02,262+0530","service":"FyersDataSocket"}
{"level":"DEBUG","location":"[<lambda>:1654] data_ws","message":"Response:Attempting reconnect 9 of 10...","timestamp":"2024-02-26 11:32:12,281+0530","service":"FyersDataSocket"}
{"level":"DEBUG","location":"[<lambda>:1654] data_ws","message":"Response:Attempting reconnect 10 of 10...","timestamp":"2024-02-26 11:32:22,297+0530","service":"FyersDataSocket"}
{"level":"DEBUG","location":"[<lambda>:1654] data_ws","message":"Response:Max reconnect attempts reached. Connection abandoned.","timestamp":"2024-02-26 11:32:32,315+0530","service":"FyersDataSocket"}
{"level":"ERROR","location":"[On_message:1434] data_ws","message":"\"Key 'orderBook' not found. If specifying a record_path, all elements of data should have the path.\"","timestamp":"2024-02-26 19:13:40,483+0530","service":"FyersDataSocket","exception":"Traceback (most recent call last):\n  File \"D:\\AlgoMaster_Trail\\venv\\Lib\\site-packages\\pandas\\io\\json\\_normalize.py\", line 398, in _pull_field\n    result = result[spec]\n             ~~~~~~^^^^^^\nKeyError: 'orderBook'\n\nThe above exception was the direct cause of the following exception:\n\nTraceback (most recent call last):\n  File \"D:\\AlgoMaster_Trail\\venv\\Lib\\site-packages\\fyers_apiv3\\FyersWebsocket\\data_ws.py\", line 1425, in On_message\n    self.OnMessage(message)\n  File \"D:\\AlgoMaster_Trail\\FyersWebSocket.py\", line 89, in onmessage\n    tmp_trd_prc = utl.get_order_traded_price(curr_order_id)\n                  ^^^^^^^^^^^^^^^^^^^^^^^^^^^^^^^^^^^^^^^^^\n  File \"D:\\AlgoMaster_Trail\\AlgoUtil.py\", line 57, in get_order_traded_price\n    tmp_orders = pd.json_normalize(fyers.orderbook(data=data), record_path=['orderBook'])\n                 ^^^^^^^^^^^^^^^^^^^^^^^^^^^^^^^^^^^^^^^^^^^^^^^^^^^^^^^^^^^^^^^^^^^^^^^^\n  File \"D:\\AlgoMaster_Trail\\venv\\Lib\\site-packages\\pandas\\io\\json\\_normalize.py\", line 517, in json_normalize\n    _recursive_extract(data, record_path, {}, level=0)\n  File \"D:\\AlgoMaster_Trail\\venv\\Lib\\site-packages\\pandas\\io\\json\\_normalize.py\", line 499, in _recursive_extract\n    recs = _pull_records(obj, path[0])\n           ^^^^^^^^^^^^^^^^^^^^^^^^^^^\n  File \"D:\\AlgoMaster_Trail\\venv\\Lib\\site-packages\\pandas\\io\\json\\_normalize.py\", line 421, in _pull_records\n    result = _pull_field(js, spec, extract_record=True)\n             ^^^^^^^^^^^^^^^^^^^^^^^^^^^^^^^^^^^^^^^^^^\n  File \"D:\\AlgoMaster_Trail\\venv\\Lib\\site-packages\\pandas\\io\\json\\_normalize.py\", line 401, in _pull_field\n    raise KeyError(\nKeyError: \"Key 'orderBook' not found. If specifying a record_path, all elements of data should have the path.\"","exception_name":"KeyError"}
{"level":"ERROR","location":"[__response_output:991] data_ws","message":"string indices must be integers, not 'str'","timestamp":"2024-02-26 19:13:40,525+0530","service":"FyersDataSocket","exception":"Traceback (most recent call last):\n  File \"D:\\AlgoMaster_Trail\\venv\\Lib\\site-packages\\pandas\\io\\json\\_normalize.py\", line 398, in _pull_field\n    result = result[spec]\n             ~~~~~~^^^^^^\nKeyError: 'orderBook'\n\nThe above exception was the direct cause of the following exception:\n\nTraceback (most recent call last):\n  File \"D:\\AlgoMaster_Trail\\venv\\Lib\\site-packages\\fyers_apiv3\\FyersWebsocket\\data_ws.py\", line 1425, in On_message\n    self.OnMessage(message)\n  File \"D:\\AlgoMaster_Trail\\FyersWebSocket.py\", line 89, in onmessage\n    tmp_trd_prc = utl.get_order_traded_price(curr_order_id)\n                  ^^^^^^^^^^^^^^^^^^^^^^^^^^^^^^^^^^^^^^^^^\n  File \"D:\\AlgoMaster_Trail\\AlgoUtil.py\", line 57, in get_order_traded_price\n    tmp_orders = pd.json_normalize(fyers.orderbook(data=data), record_path=['orderBook'])\n                 ^^^^^^^^^^^^^^^^^^^^^^^^^^^^^^^^^^^^^^^^^^^^^^^^^^^^^^^^^^^^^^^^^^^^^^^^\n  File \"D:\\AlgoMaster_Trail\\venv\\Lib\\site-packages\\pandas\\io\\json\\_normalize.py\", line 517, in json_normalize\n    _recursive_extract(data, record_path, {}, level=0)\n  File \"D:\\AlgoMaster_Trail\\venv\\Lib\\site-packages\\pandas\\io\\json\\_normalize.py\", line 499, in _recursive_extract\n    recs = _pull_records(obj, path[0])\n           ^^^^^^^^^^^^^^^^^^^^^^^^^^^\n  File \"D:\\AlgoMaster_Trail\\venv\\Lib\\site-packages\\pandas\\io\\json\\_normalize.py\", line 421, in _pull_records\n    result = _pull_field(js, spec, extract_record=True)\n             ^^^^^^^^^^^^^^^^^^^^^^^^^^^^^^^^^^^^^^^^^^\n  File \"D:\\AlgoMaster_Trail\\venv\\Lib\\site-packages\\pandas\\io\\json\\_normalize.py\", line 401, in _pull_field\n    raise KeyError(\nKeyError: \"Key 'orderBook' not found. If specifying a record_path, all elements of data should have the path.\"\n\nDuring handling of the above exception, another exception occurred:\n\nTraceback (most recent call last):\n  File \"D:\\AlgoMaster_Trail\\venv\\Lib\\site-packages\\fyers_apiv3\\FyersWebsocket\\data_ws.py\", line 988, in __response_output\n    self.On_message(response)\n  File \"D:\\AlgoMaster_Trail\\venv\\Lib\\site-packages\\fyers_apiv3\\FyersWebsocket\\data_ws.py\", line 1435, in On_message\n    self.On_error(f\"KeyError: The key {key_name} is missing in the response.\")\n  File \"D:\\AlgoMaster_Trail\\venv\\Lib\\site-packages\\fyers_apiv3\\FyersWebsocket\\data_ws.py\", line 1492, in On_error\n    self.OnError(message)\n  File \"D:\\AlgoMaster_Trail\\FyersWebSocket.py\", line 108, in onerror\n    messages.append(\"Error: \" + str(message[\"message\"] ))\n                                    ~~~~~~~^^^^^^^^^^^\nTypeError: string indices must be integers, not 'str'","exception_name":"TypeError"}
